<?xml version='1.0'?>
<sdf version='1.0'>
  <model name="wheel_ball">
    <static>false</static>
    <link name="obstacle_1">
      <pose>0 0 0 0 0 0</pose>
        <inertial>
          <inertia>
            <ixx>0.101</ixx>
            <ixy>0</ixy>
            <ixz>0</ixz>
            <iyy>0.901</iyy>
            <iyz>0</iyz>
            <izz>1.1</izz>
          </inertia>
          <mass>1.8</mass>
        </inertial>

        <collision name="my_collision">
            <geometry>
             <box>
             <size>3.0 1.0 0.1</size>
             </box>
            </geometry>

        </collision>

        <visual name="my_visual">
            <geometry>
             <box>
             <size>3.0 1.0 0.1</size>
             </box>
            </geometry>
        </visual>
    </link>

    <link name="obstacle_2">
      <pose>1 1 0 0 0 0</pose>
        <inertial>
          <inertia>
            <ixx>0.033666666</ixx>
            <ixy>0</ixy>
            <ixz>0</ixz>
            <iyy>0.033666666</iyy>
            <iyz>0</iyz>
            <izz>0.066666666</izz>
          </inertia>
          <mass>0.6</mass>
        </inertial>

        <collision name="my_collision">
            <geometry>
             <box>
             <size>1.0 1.0 0.1</size>
             </box>
            </geometry>

        </collision>

        <visual name="my_visual">
            <geometry>
             <box>
             <size>1.0 1.0 0.1</size>
             </box>
            </geometry>
        </visual>
    </link>

    <joint name="obstacle_joint" type="fixed">
      <parent>obstacle_1</parent>
      <child>obstacle_2</child>
      <pose>0.00 0.0 0.0 0 0.0 0.0</pose>
    </joint>

    <link name="payload_link_1">
      <pose>-1.55 0 0 0 0 0</pose>
        <inertial>
          <inertia>
            <ixx>0.0000666</ixx>
            <ixy>0</ixy>
            <ixz>0</ixz>
            <iyy>0.0000666</iyy>
            <iyz>0</iyz>
            <izz>0.0000666</izz>
          </inertia>
          <mass>0.04</mass>
        </inertial>

        <collision name="payload_link_1_collision">
            <geometry>
             <box>
             <size>0.1 0.1 0.1</size>
             </box>
            </geometry>

        </collision>

        <visual name="payload_link_1_visual">
            <geometry>
             <box>
             <size>0.1 0.1 0.1</size>
             </box>
            </geometry>
        </visual>
    </link>

    <joint name="payload_joint_1" type="fixed">
      <parent>obstacle_1</parent>
      <child>payload_link_1</child>
      <pose>0.05 0 0 0 0 0</pose>
      <axis>
        <xyz>1 0 0</xyz>
        <limit>
          <upper>0</upper>
          <lower>0</lower>
        </limit>
      </axis>
      <sensor name="force_torque" type="force_torque">
        <update_rate>100.0</update_rate>
        <always_on>true</always_on>
        <visualize>true</visualize>
        <measure_direction>child_to_parent</measure_direction>
      </sensor>
    </joint>

    <link name="payload_link_2">
      <pose>1 -0.55 0 0 0 0</pose>
        <inertial>
          <inertia>
            <ixx>0.0000666</ixx>
            <ixy>0</ixy>
            <ixz>0</ixz>
            <iyy>0.0000666</iyy>
            <iyz>0</iyz>
            <izz>0.0000666</izz>
          </inertia>
          <mass>0.04</mass>
        </inertial>

        <collision name="payload_link_2_collision">
            <geometry>
             <box>
             <size>0.1 0.1 0.1</size>
             </box>
            </geometry>

        </collision>

        <visual name="payload_link_2_visual">
            <geometry>
             <box>
             <size>0.1 0.1 0.1</size>
             </box>
            </geometry>
        </visual>
    </link>

    <joint name="payload_joint_2" type="fixed">
      <parent>obstacle_1</parent>
      <child>payload_link_2</child>
      <pose>0 0.05 0 0 0 0</pose>
      <axis>
        <xyz>0 0 1</xyz>
        <limit>
          <upper>0</upper>
          <lower>0</lower>
        </limit>
      </axis>
      <sensor name="force_torque" type="force_torque">
        <update_rate>100.0</update_rate>
        <always_on>true</always_on>
        <visualize>true</visualize>
      </sensor>
    </joint>

    <link name="payload_link_3">
      <pose>1.55 1.45 0 0 0 0</pose>
        <inertial>
          <inertia>
            <ixx>0.0000666</ixx>
            <ixy>0</ixy>
            <ixz>0</ixz>
            <iyy>0.0000666</iyy>
            <iyz>0</iyz>
            <izz>0.0000666</izz>
          </inertia>
          <mass>0.04</mass>
        </inertial>

        <collision name="payload_link_3_collision">
            <geometry>
             <box>
             <size>0.1 0.1 0.1</size>
             </box>
            </geometry>

        </collision>

        <visual name="payload_link_3_visual">
            <geometry>
             <box>
             <size>0.1 0.1 0.1</size>
             </box>
            </geometry>
        </visual>
    </link>

    <joint name="payload_joint_3" type="fixed">
      <parent>obstacle_2</parent>
      <child>payload_link_3</child>
      <pose>-0.05 0 0 0 0 0</pose>
      <axis>
        <xyz>0 0 1</xyz>
        <limit>
          <upper>0</upper>
          <lower>0</lower>
        </limit>
      </axis>
      <sensor name="force_torque" type="force_torque">
        <update_rate>100.0</update_rate>
        <always_on>true</always_on>
        <visualize>true</visualize>
      </sensor>
    </joint>

    <link name='ball_1'>
      <pose>-1.55 0 -0.3 0 0 0</pose>
      <inertial>
        <inertia>
          <ixx>0.0016</ixx>
          <ixy>0</ixy>
          <ixz>0</ixz>
          <iyy>0.0016</iyy>
          <iyz>0</iyz>
          <izz>0.0016</izz>
          </inertia>
        <mass>0.1</mass>
      </inertial>
      <collision name='ball_1_collision'>
        <geometry>
          <sphere>
            <radius>0.2</radius>
          </sphere>
        </geometry>
      </collision>
      <visual name='ball_1_visual'>
        <geometry>
          <sphere>
            <radius>0.2</radius>
          </sphere>
        </geometry>
        <material>
          <diffuse>1 0 0 1</diffuse>
          <ambient>1 0 0 1</ambient>
        </material>
      </visual>
    </link>
    <joint name="ball_1_joint" type="ball">
      <parent>payload_link_1</parent>
      <child>ball_1</child>
      <pose> 0 0 0 0 0 0 </pose>
      <sensor name="force_torque" type="force_torque">
        <update_rate>50.0</update_rate>
        <always_on>true</always_on>
      </sensor>
    </joint>

    <joint name="ball_1_ground" type="revolute2">
      <parent>world</parent>
      <child>ball_1</child>
      <sensor name="force_torque" type="force_torque">
        <update_rate>50.0</update_rate>
        <always_on>true</always_on>
      </sensor>
    </joint>

    <link name='ball_2'>
      <pose>1 -0.55 -0.3 0 0 0</pose>
      <inertial>
        <inertia>
          <ixx>0.0016</ixx>
          <ixy>0</ixy>
          <ixz>0</ixz>
          <iyy>0.0016</iyy>
          <iyz>0</iyz>
          <izz>0.0016</izz>
          </inertia>
        <mass>0.1</mass>
      </inertial>
      <collision name='ball_2_collision'>
        <geometry>
          <sphere>
            <radius>0.2</radius>
          </sphere>
        </geometry>
      </collision>
      <visual name='ball_2_visual'>
        <geometry>
          <sphere>
            <radius>0.2</radius>
          </sphere>
        </geometry>
        <material>
          <diffuse>1 0 0 1</diffuse>
          <ambient>1 0 0 1</ambient>
        </material>
      </visual>
    </link>
    <joint name="ball_2_joint" type="ball">
      <parent>payload_link_2</parent>
      <child>ball_2</child>
      <pose> 0 0 0 0 0 0 </pose>
    </joint>

    <link name='ball_3'>
      <pose>1.55 1.45 -0.3 0 0 0</pose>
      <inertial>
        <inertia>
          <ixx>0.0016</ixx>
          <ixy>0</ixy>
          <ixz>0</ixz>
          <iyy>0.0016</iyy>
          <iyz>0</iyz>
          <izz>0.0016</izz>
          </inertia>
        <mass>0.1</mass>
      </inertial>
      <collision name='ball_3_collision'>
        <geometry>
          <sphere>
            <radius>0.2</radius>
          </sphere>
        </geometry>
      </collision>
      <visual name='ball_3_visual'>
        <geometry>
          <sphere>
            <radius>0.2</radius>
          </sphere>
        </geometry>
        <material>
          <diffuse>1 0 0 1</diffuse>
          <ambient>1 0 0 1</ambient>
        </material>
      </visual>
    </link>
    <joint name="ball_3_joint" type="ball">
      <parent>payload_link_3</parent>
      <child>ball_3</child>
      <pose> 0 0 0 0 0 0 </pose>
    </joint>


    <link name="payload_IMU">
      <pose>0 0 0.06 0 0 0</pose>
        <inertial>
          <inertia>
            <ixx>0.000004165</ixx>
            <ixy>0</ixy>
            <ixz>0</ixz>
            <iyy>0.000185</iyy>
            <iyz>0</iyz>
            <izz>0.000185</izz>
          </inertia>
          <mass>0.0001</mass>
        </inertial>

        <collision name="payload_IMU_collision">
            <geometry>
             <box>
             <size>0.01 0.01 0.01</size>
             </box>
            </geometry>

        </collision>

        <visual name="payload_IMU_visual">
            <geometry>
             <box>
             <size>0.01 0.01 0.01</size>
             </box>
            </geometry>
        </visual>

        <sensor name="IMU" type="imu">
          <plugin name="IMU_plugin" filename="libgazebo_ros_imu_sensor.so">
            <always_on>true</always_on>
              <topicName>/IMU</topicName>
              <updateRateHZ>50</updateRateHZ>
              <frameName>payload_IMU</frameName>
          </plugin>
        </sensor>
    </link>

    <joint name="payload_imu_joint" type="fixed">
      <parent>obstacle_1</parent>
      <child>payload_IMU</child>
      <pose>0.00 0.0 0.0 0 0.0 0.0</pose>
    </joint>


    <joint name="payload_link_12" type="fixed">
      <parent>payload_link_1</parent>
      <child>payload_link_2</child>
      <pose>0 0 0 0 0 0</pose>
      <axis>
        <xyz>0 0 1</xyz>
        <limit>
          <upper>0</upper>
          <lower>0</lower>
        </limit>
      </axis>
    </joint>
    <joint name="payload_link_23" type="fixed">
      <parent>payload_link_2</parent>
      <child>payload_link_3</child>
      <pose>0 0 0 0 0 0</pose>
      <axis>
        <xyz>0 0 1</xyz>
        <limit>
          <upper>0</upper>
          <lower>0</lower>
        </limit>
      </axis>
    </joint>
    <joint name="payload_link_13" type="fixed">
      <parent>payload_link_1</parent>
      <child>payload_link_3</child>
      <axis>
        <xyz>0 0 1</xyz>
        <limit>
          <upper>0</upper>
          <lower>0</lower>
        </limit>
      </axis>
      <pose>0 0 0 0 0 0</pose>
    </joint>


    <plugin name="p3d_base_controller" filename="libgazebo_ros_p3d.so">
      <alwaysOn>true</alwaysOn>
      <updateRate>50.0</updateRate>
      <bodyName>payload_IMU</bodyName>
      <topicName>position</topicName>
      <gaussianNoise>0.01</gaussianNoise>
      <frameName>world</frameName>
      <xyzOffsets>0 0 0</xyzOffsets>
      <rpyOffsets>0 0 0</rpyOffsets>
    </plugin>

    <plugin name="ft_sensor" filename="libgazebo_ros_ft_sensor.so">
      <always_on>true</always_on>
      <updateRate>10.0</updateRate>
      <topicName>/payload_joint_1_ft_sensor</topicName>
      <jointName>payload_joint_1</jointName>
    </plugin>
    <plugin name="ft_sensor" filename="libgazebo_ros_ft_sensor.so">
      <always_on>true</always_on>
      <updateRate>10.0</updateRate>
      <topicName>/payload_joint_2_ft_sensor</topicName>
      <jointName>payload_joint_2</jointName>
    </plugin>
    <plugin name="ft_sensor" filename="libgazebo_ros_ft_sensor.so">
      <always_on>true</always_on>
      <updateRate>10.0</updateRate>
      <topicName>/payload_joint_3_ft_sensor</topicName>
      <jointName>payload_joint_3</jointName>
    </plugin>

    <plugin name="ft_sensor" filename="libgazebo_ros_ft_sensor.so">
      <always_on>true</always_on>
      <updateRate>50.0</updateRate>
      <topicName>ball_1_joint_ft_sensor</topicName>
      <jointName>ball_1_joint</jointName>
    </plugin>

    <plugin name="ft_sensor" filename="libgazebo_ros_ft_sensor.so">
      <always_on>true</always_on>
      <updateRate>50.0</updateRate>
      <topicName>/ball_1_ground_ft_sensor</topicName>
      <jointName>ball_1_ground</jointName>
    </plugin><!---->

  </model>
</sdf>
